wandb: Currently logged in as: stevenzhou0816100. Use `wandb login --relogin` to force relogin
The following values were not passed to `accelerate launch` and had defaults used instead:
		More than one GPU was found, enabling multi-GPU training.
		If this was unintended please pass in `--num_processes=1`.
	`--mixed_precision` was set to a value of `'no'`
	`--dynamo_backend` was set to a value of `'no'`
To avoid this warning pass in values for each of the problematic parameters or run `accelerate config`.
/data/home/beidic/anaconda3/envs/yangllm2/bin/python3.9: can't open file '/opt/hpcaas/.mounts/fs-03efe25c053395d1f/beidic/yang/transformersprofiling/largesmallfinetuning_mseplusceloss2.py': [Errno 2] No such file or directory
/data/home/beidic/anaconda3/envs/yangllm2/bin/python3.9: can't open file '/opt/hpcaas/.mounts/fs-03efe25c053395d1f/beidic/yang/transformersprofiling/largesmallfinetuning_mseplusceloss2.py': [Errno 2] No such file or directory
/data/home/beidic/anaconda3/envs/yangllm2/bin/python3.9: can't open file '/opt/hpcaas/.mounts/fs-03efe25c053395d1f/beidic/yang/transformersprofiling/largesmallfinetuning_mseplusceloss2.py': [Errno 2] No such file or directory
/data/home/beidic/anaconda3/envs/yangllm2/bin/python3.9: can't open file '/opt/hpcaas/.mounts/fs-03efe25c053395d1f/beidic/yang/transformersprofiling/largesmallfinetuning_mseplusceloss2.py': [Errno 2] No such file or directory
/data/home/beidic/anaconda3/envs/yangllm2/bin/python3.9: can't open file '/opt/hpcaas/.mounts/fs-03efe25c053395d1f/beidic/yang/transformersprofiling/largesmallfinetuning_mseplusceloss2.py': [Errno 2] No such file or directory
/data/home/beidic/anaconda3/envs/yangllm2/bin/python3.9: can't open file '/opt/hpcaas/.mounts/fs-03efe25c053395d1f/beidic/yang/transformersprofiling/largesmallfinetuning_mseplusceloss2.py': [Errno 2] No such file or directory
/data/home/beidic/anaconda3/envs/yangllm2/bin/python3.9: can't open file '/opt/hpcaas/.mounts/fs-03efe25c053395d1f/beidic/yang/transformersprofiling/largesmallfinetuning_mseplusceloss2.py': [Errno 2] No such file or directory
/data/home/beidic/anaconda3/envs/yangllm2/bin/python3.9: can't open file '/opt/hpcaas/.mounts/fs-03efe25c053395d1f/beidic/yang/transformersprofiling/largesmallfinetuning_mseplusceloss2.py': [Errno 2] No such file or directory
[2024-03-14 13:22:18,403] torch.distributed.elastic.multiprocessing.api: [ERROR] failed (exitcode: 2) local_rank: 0 (pid: 3046836) of binary: /data/home/beidic/anaconda3/envs/yangllm2/bin/python3.9
Traceback (most recent call last):
  File "/data/home/beidic/anaconda3/envs/yangllm2/bin/accelerate", line 8, in <module>
    sys.exit(main())
  File "/data/home/beidic/anaconda3/envs/yangllm2/lib/python3.9/site-packages/accelerate/commands/accelerate_cli.py", line 47, in main
    args.func(args)
  File "/data/home/beidic/anaconda3/envs/yangllm2/lib/python3.9/site-packages/accelerate/commands/launch.py", line 1014, in launch_command
    multi_gpu_launcher(args)
  File "/data/home/beidic/anaconda3/envs/yangllm2/lib/python3.9/site-packages/accelerate/commands/launch.py", line 672, in multi_gpu_launcher
    distrib_run.run(args)
  File "/data/home/beidic/anaconda3/envs/yangllm2/lib/python3.9/site-packages/torch/distributed/run.py", line 797, in run
    elastic_launch(
  File "/data/home/beidic/anaconda3/envs/yangllm2/lib/python3.9/site-packages/torch/distributed/launcher/api.py", line 134, in __call__
    return launch_agent(self._config, self._entrypoint, list(args))
  File "/data/home/beidic/anaconda3/envs/yangllm2/lib/python3.9/site-packages/torch/distributed/launcher/api.py", line 264, in launch_agent
    raise ChildFailedError(
torch.distributed.elastic.multiprocessing.errors.ChildFailedError: 
============================================================
largesmallfinetuning_mseplusceloss2.py FAILED
------------------------------------------------------------
Failures:
[1]:
  time      : 2024-03-14_13:22:18
  host      : a100-st-p4de24xlarge-1029.fair-a100.hpcaas
  rank      : 1 (local_rank: 1)
  exitcode  : 2 (pid: 3046844)
  error_file: <N/A>
  traceback : To enable traceback see: https://pytorch.org/docs/stable/elastic/errors.html
[2]:
  time      : 2024-03-14_13:22:18
  host      : a100-st-p4de24xlarge-1029.fair-a100.hpcaas
  rank      : 2 (local_rank: 2)
  exitcode  : 2 (pid: 3046845)
  error_file: <N/A>
  traceback : To enable traceback see: https://pytorch.org/docs/stable/elastic/errors.html
[3]:
  time      : 2024-03-14_13:22:18
  host      : a100-st-p4de24xlarge-1029.fair-a100.hpcaas
  rank      : 3 (local_rank: 3)
  exitcode  : 2 (pid: 3046846)
  error_file: <N/A>
  traceback : To enable traceback see: https://pytorch.org/docs/stable/elastic/errors.html
[4]:
  time      : 2024-03-14_13:22:18
  host      : a100-st-p4de24xlarge-1029.fair-a100.hpcaas
  rank      : 4 (local_rank: 4)
  exitcode  : 2 (pid: 3046847)
  error_file: <N/A>
  traceback : To enable traceback see: https://pytorch.org/docs/stable/elastic/errors.html
[5]:
  time      : 2024-03-14_13:22:18
  host      : a100-st-p4de24xlarge-1029.fair-a100.hpcaas
  rank      : 5 (local_rank: 5)
  exitcode  : 2 (pid: 3046848)
  error_file: <N/A>
  traceback : To enable traceback see: https://pytorch.org/docs/stable/elastic/errors.html
[6]:
  time      : 2024-03-14_13:22:18
  host      : a100-st-p4de24xlarge-1029.fair-a100.hpcaas
  rank      : 6 (local_rank: 6)
  exitcode  : 2 (pid: 3046849)
  error_file: <N/A>
  traceback : To enable traceback see: https://pytorch.org/docs/stable/elastic/errors.html
[7]:
  time      : 2024-03-14_13:22:18
  host      : a100-st-p4de24xlarge-1029.fair-a100.hpcaas
  rank      : 7 (local_rank: 7)
  exitcode  : 2 (pid: 3046850)
  error_file: <N/A>
  traceback : To enable traceback see: https://pytorch.org/docs/stable/elastic/errors.html
------------------------------------------------------------
Root Cause (first observed failure):
[0]:
  time      : 2024-03-14_13:22:18
  host      : a100-st-p4de24xlarge-1029.fair-a100.hpcaas
  rank      : 0 (local_rank: 0)
  exitcode  : 2 (pid: 3046836)
  error_file: <N/A>
  traceback : To enable traceback see: https://pytorch.org/docs/stable/elastic/errors.html
============================================================
