wandb: Currently logged in as: stevenzhou0816100. Use `wandb login --relogin` to force relogin
The following values were not passed to `accelerate launch` and had defaults used instead:
		More than one GPU was found, enabling multi-GPU training.
		If this was unintended please pass in `--num_processes=1`.
	`--mixed_precision` was set to a value of `'no'`
	`--dynamo_backend` was set to a value of `'no'`
To avoid this warning pass in values for each of the problematic parameters or run `accelerate config`.
Traceback (most recent call last):
Traceback (most recent call last):
  File "/opt/hpcaas/.mounts/fs-03efe25c053395d1f/beidic/yang/transformersprofiling/weird_training_largeplussmall.py", line 1057, in <module>
  File "/opt/hpcaas/.mounts/fs-03efe25c053395d1f/beidic/yang/transformersprofiling/weird_training_largeplussmall.py", line 1057, in <module>
    assert args.finetuned_checkpoint is not None 
AttributeError: 'Namespace' object has no attribute 'finetuned_checkpoint'
Traceback (most recent call last):
  File "/opt/hpcaas/.mounts/fs-03efe25c053395d1f/beidic/yang/transformersprofiling/weird_training_largeplussmall.py", line 1057, in <module>
    assert args.finetuned_checkpoint is not None 
AttributeErrorTraceback (most recent call last):
:   File "/opt/hpcaas/.mounts/fs-03efe25c053395d1f/beidic/yang/transformersprofiling/weird_training_largeplussmall.py", line 1057, in <module>
'Namespace' object has no attribute 'finetuned_checkpoint'Traceback (most recent call last):

  File "/opt/hpcaas/.mounts/fs-03efe25c053395d1f/beidic/yang/transformersprofiling/weird_training_largeplussmall.py", line 1057, in <module>
    assert args.finetuned_checkpoint is not None 
AttributeError: 'Namespace' object has no attribute 'finetuned_checkpoint'
    assert args.finetuned_checkpoint is not None 
AttributeError: 'Namespace' object has no attribute 'finetuned_checkpoint'
    assert args.finetuned_checkpoint is not None 
AttributeError: 'Namespace' object has no attribute 'finetuned_checkpoint'
Traceback (most recent call last):
  File "/opt/hpcaas/.mounts/fs-03efe25c053395d1f/beidic/yang/transformersprofiling/weird_training_largeplussmall.py", line 1057, in <module>
Traceback (most recent call last):
  File "/opt/hpcaas/.mounts/fs-03efe25c053395d1f/beidic/yang/transformersprofiling/weird_training_largeplussmall.py", line 1057, in <module>
Traceback (most recent call last):
  File "/opt/hpcaas/.mounts/fs-03efe25c053395d1f/beidic/yang/transformersprofiling/weird_training_largeplussmall.py", line 1057, in <module>
        assert args.finetuned_checkpoint is not None assert args.finetuned_checkpoint is not None 

AttributeErrorAttributeError: : 'Namespace' object has no attribute 'finetuned_checkpoint''Namespace' object has no attribute 'finetuned_checkpoint'

    assert args.finetuned_checkpoint is not None 
AttributeError: 'Namespace' object has no attribute 'finetuned_checkpoint'
[2024-04-24 05:24:25,173] torch.distributed.elastic.multiprocessing.api: [WARNING] Sending process 354920 closing signal SIGTERM
[2024-04-24 05:24:25,174] torch.distributed.elastic.multiprocessing.api: [WARNING] Sending process 354924 closing signal SIGTERM
[2024-04-24 05:24:25,538] torch.distributed.elastic.multiprocessing.api: [ERROR] failed (exitcode: 1) local_rank: 0 (pid: 354918) of binary: /data/home/beidic/anaconda3/envs/yangllm2/bin/python3.9
Traceback (most recent call last):
  File "/data/home/beidic/anaconda3/envs/yangllm2/bin/accelerate", line 8, in <module>
    sys.exit(main())
  File "/data/home/beidic/anaconda3/envs/yangllm2/lib/python3.9/site-packages/accelerate/commands/accelerate_cli.py", line 47, in main
    args.func(args)
  File "/data/home/beidic/anaconda3/envs/yangllm2/lib/python3.9/site-packages/accelerate/commands/launch.py", line 1014, in launch_command
    multi_gpu_launcher(args)
  File "/data/home/beidic/anaconda3/envs/yangllm2/lib/python3.9/site-packages/accelerate/commands/launch.py", line 672, in multi_gpu_launcher
    distrib_run.run(args)
  File "/data/home/beidic/anaconda3/envs/yangllm2/lib/python3.9/site-packages/torch/distributed/run.py", line 797, in run
    elastic_launch(
  File "/data/home/beidic/anaconda3/envs/yangllm2/lib/python3.9/site-packages/torch/distributed/launcher/api.py", line 134, in __call__
    return launch_agent(self._config, self._entrypoint, list(args))
  File "/data/home/beidic/anaconda3/envs/yangllm2/lib/python3.9/site-packages/torch/distributed/launcher/api.py", line 264, in launch_agent
    raise ChildFailedError(
torch.distributed.elastic.multiprocessing.errors.ChildFailedError: 
============================================================
weird_training_largeplussmall.py FAILED
------------------------------------------------------------
Failures:
[1]:
  time      : 2024-04-24_05:24:25
  host      : a100-st-p4de24xlarge-1036.fair-a100.hpcaas
  rank      : 1 (local_rank: 1)
  exitcode  : 1 (pid: 354919)
  error_file: <N/A>
  traceback : To enable traceback see: https://pytorch.org/docs/stable/elastic/errors.html
[2]:
  time      : 2024-04-24_05:24:25
  host      : a100-st-p4de24xlarge-1036.fair-a100.hpcaas
  rank      : 3 (local_rank: 3)
  exitcode  : 1 (pid: 354921)
  error_file: <N/A>
  traceback : To enable traceback see: https://pytorch.org/docs/stable/elastic/errors.html
[3]:
  time      : 2024-04-24_05:24:25
  host      : a100-st-p4de24xlarge-1036.fair-a100.hpcaas
  rank      : 4 (local_rank: 4)
  exitcode  : 1 (pid: 354922)
  error_file: <N/A>
  traceback : To enable traceback see: https://pytorch.org/docs/stable/elastic/errors.html
[4]:
  time      : 2024-04-24_05:24:25
  host      : a100-st-p4de24xlarge-1036.fair-a100.hpcaas
  rank      : 5 (local_rank: 5)
  exitcode  : 1 (pid: 354923)
  error_file: <N/A>
  traceback : To enable traceback see: https://pytorch.org/docs/stable/elastic/errors.html
[5]:
  time      : 2024-04-24_05:24:25
  host      : a100-st-p4de24xlarge-1036.fair-a100.hpcaas
  rank      : 7 (local_rank: 7)
  exitcode  : 1 (pid: 354925)
  error_file: <N/A>
  traceback : To enable traceback see: https://pytorch.org/docs/stable/elastic/errors.html
------------------------------------------------------------
Root Cause (first observed failure):
[0]:
  time      : 2024-04-24_05:24:25
  host      : a100-st-p4de24xlarge-1036.fair-a100.hpcaas
  rank      : 0 (local_rank: 0)
  exitcode  : 1 (pid: 354918)
  error_file: <N/A>
  traceback : To enable traceback see: https://pytorch.org/docs/stable/elastic/errors.html
============================================================
