wandb: Currently logged in as: stevenzhou0816100. Use `wandb login --relogin` to force relogin
The following values were not passed to `accelerate launch` and had defaults used instead:
		More than one GPU was found, enabling multi-GPU training.
		If this was unintended please pass in `--num_processes=1`.
	`--mixed_precision` was set to a value of `'no'`
	`--dynamo_backend` was set to a value of `'no'`
To avoid this warning pass in values for each of the problematic parameters or run `accelerate config`.
Traceback (most recent call last):
  File "/opt/hpcaas/.mounts/fs-03efe25c053395d1f/beidic/yang/transformersprofiling/largemodelfinetuning_mseplusceloss2.py", line 934, in <module>
Traceback (most recent call last):
  File "/opt/hpcaas/.mounts/fs-03efe25c053395d1f/beidic/yang/transformersprofiling/largemodelfinetuning_mseplusceloss2.py", line 934, in <module>
    train_dataset = CustomDataset(max_length = args.max_length, data_dir = dir_c4_parts, large_tokenizer = large_tokenizer, small_tokenizer = small_tokenizer, kernel_size = kernel_size, topk = args.topk, prompt_length = 64, use_c4 = args.use_c4, in_training = True) 
  File "/opt/hpcaas/.mounts/fs-03efe25c053395d1f/beidic/yang/transformersprofiling/largemodelfinetuning_mseplusceloss2.py", line 756, in __init__
    self.dataset = load_dataset('json', data_files = dfiles, split = "train") 
  File "/data/home/beidic/anaconda3/envs/yangllm2/lib/python3.9/site-packages/datasets/load.py", line 2548, in load_dataset
    train_dataset = CustomDataset(max_length = args.max_length, data_dir = dir_c4_parts, large_tokenizer = large_tokenizer, small_tokenizer = small_tokenizer, kernel_size = kernel_size, topk = args.topk, prompt_length = 64, use_c4 = args.use_c4, in_training = True) 
  File "/opt/hpcaas/.mounts/fs-03efe25c053395d1f/beidic/yang/transformersprofiling/largemodelfinetuning_mseplusceloss2.py", line 756, in __init__
Traceback (most recent call last):
  File "/opt/hpcaas/.mounts/fs-03efe25c053395d1f/beidic/yang/transformersprofiling/largemodelfinetuning_mseplusceloss2.py", line 934, in <module>
Traceback (most recent call last):
  File "/opt/hpcaas/.mounts/fs-03efe25c053395d1f/beidic/yang/transformersprofiling/largemodelfinetuning_mseplusceloss2.py", line 934, in <module>
        self.dataset = load_dataset('json', data_files = dfiles, split = "train") train_dataset = CustomDataset(max_length = args.max_length, data_dir = dir_c4_parts, large_tokenizer = large_tokenizer, small_tokenizer = small_tokenizer, kernel_size = kernel_size, topk = args.topk, prompt_length = 64, use_c4 = args.use_c4, in_training = True) 

  File "/data/home/beidic/anaconda3/envs/yangllm2/lib/python3.9/site-packages/datasets/load.py", line 2548, in load_dataset
  File "/opt/hpcaas/.mounts/fs-03efe25c053395d1f/beidic/yang/transformersprofiling/largemodelfinetuning_mseplusceloss2.py", line 756, in __init__
    self.dataset = load_dataset('json', data_files = dfiles, split = "train") 
  File "/data/home/beidic/anaconda3/envs/yangllm2/lib/python3.9/site-packages/datasets/load.py", line 2548, in load_dataset
    train_dataset = CustomDataset(max_length = args.max_length, data_dir = dir_c4_parts, large_tokenizer = large_tokenizer, small_tokenizer = small_tokenizer, kernel_size = kernel_size, topk = args.topk, prompt_length = 64, use_c4 = args.use_c4, in_training = True) 
  File "/opt/hpcaas/.mounts/fs-03efe25c053395d1f/beidic/yang/transformersprofiling/largemodelfinetuning_mseplusceloss2.py", line 756, in __init__
    self.dataset = load_dataset('json', data_files = dfiles, split = "train") 
  File "/data/home/beidic/anaconda3/envs/yangllm2/lib/python3.9/site-packages/datasets/load.py", line 2548, in load_dataset
            builder_instance = load_dataset_builder(builder_instance = load_dataset_builder(builder_instance = load_dataset_builder(


  File "/data/home/beidic/anaconda3/envs/yangllm2/lib/python3.9/site-packages/datasets/load.py", line 2220, in load_dataset_builder
  File "/data/home/beidic/anaconda3/envs/yangllm2/lib/python3.9/site-packages/datasets/load.py", line 2220, in load_dataset_builder
  File "/data/home/beidic/anaconda3/envs/yangllm2/lib/python3.9/site-packages/datasets/load.py", line 2220, in load_dataset_builder
    builder_instance = load_dataset_builder(
  File "/data/home/beidic/anaconda3/envs/yangllm2/lib/python3.9/site-packages/datasets/load.py", line 2220, in load_dataset_builder
            dataset_module = dataset_module_factory(dataset_module = dataset_module_factory(dataset_module = dataset_module_factory(


  File "/data/home/beidic/anaconda3/envs/yangllm2/lib/python3.9/site-packages/datasets/load.py", line 1755, in dataset_module_factory
  File "/data/home/beidic/anaconda3/envs/yangllm2/lib/python3.9/site-packages/datasets/load.py", line 1755, in dataset_module_factory
  File "/data/home/beidic/anaconda3/envs/yangllm2/lib/python3.9/site-packages/datasets/load.py", line 1755, in dataset_module_factory
    dataset_module = dataset_module_factory(    
return PackagedDatasetModuleFactory(      File "/data/home/beidic/anaconda3/envs/yangllm2/lib/python3.9/site-packages/datasets/load.py", line 1755, in dataset_module_factory

return PackagedDatasetModuleFactory(  File "/data/home/beidic/anaconda3/envs/yangllm2/lib/python3.9/site-packages/datasets/load.py", line 1129, in get_module

  File "/data/home/beidic/anaconda3/envs/yangllm2/lib/python3.9/site-packages/datasets/load.py", line 1129, in get_module
    return PackagedDatasetModuleFactory(
  File "/data/home/beidic/anaconda3/envs/yangllm2/lib/python3.9/site-packages/datasets/load.py", line 1129, in get_module
    return PackagedDatasetModuleFactory(
  File "/data/home/beidic/anaconda3/envs/yangllm2/lib/python3.9/site-packages/datasets/load.py", line 1129, in get_module
        data_files = DataFilesDict.from_patterns(data_files = DataFilesDict.from_patterns(

  File "/data/home/beidic/anaconda3/envs/yangllm2/lib/python3.9/site-packages/datasets/data_files.py", line 693, in from_patterns
  File "/data/home/beidic/anaconda3/envs/yangllm2/lib/python3.9/site-packages/datasets/data_files.py", line 693, in from_patterns
    data_files = DataFilesDict.from_patterns(
  File "/data/home/beidic/anaconda3/envs/yangllm2/lib/python3.9/site-packages/datasets/data_files.py", line 693, in from_patterns
    data_files = DataFilesDict.from_patterns(
  File "/data/home/beidic/anaconda3/envs/yangllm2/lib/python3.9/site-packages/datasets/data_files.py", line 693, in from_patterns
            DataFilesList.from_patterns(DataFilesList.from_patterns(DataFilesList.from_patterns(


  File "/data/home/beidic/anaconda3/envs/yangllm2/lib/python3.9/site-packages/datasets/data_files.py", line 598, in from_patterns
  File "/data/home/beidic/anaconda3/envs/yangllm2/lib/python3.9/site-packages/datasets/data_files.py", line 598, in from_patterns
  File "/data/home/beidic/anaconda3/envs/yangllm2/lib/python3.9/site-packages/datasets/data_files.py", line 598, in from_patterns
    DataFilesList.from_patterns(
  File "/data/home/beidic/anaconda3/envs/yangllm2/lib/python3.9/site-packages/datasets/data_files.py", line 598, in from_patterns
Traceback (most recent call last):
  File "/opt/hpcaas/.mounts/fs-03efe25c053395d1f/beidic/yang/transformersprofiling/largemodelfinetuning_mseplusceloss2.py", line 934, in <module>
            resolve_pattern(resolve_pattern(resolve_pattern(


  File "/data/home/beidic/anaconda3/envs/yangllm2/lib/python3.9/site-packages/datasets/data_files.py", line 386, in resolve_pattern
  File "/data/home/beidic/anaconda3/envs/yangllm2/lib/python3.9/site-packages/datasets/data_files.py", line 386, in resolve_pattern
  File "/data/home/beidic/anaconda3/envs/yangllm2/lib/python3.9/site-packages/datasets/data_files.py", line 386, in resolve_pattern
    resolve_pattern(
  File "/data/home/beidic/anaconda3/envs/yangllm2/lib/python3.9/site-packages/datasets/data_files.py", line 386, in resolve_pattern
        raise FileNotFoundError(error_msg)raise FileNotFoundError(error_msg)

    FileNotFoundErrorFileNotFoundErrorraise FileNotFoundError(error_msg): : 
Unable to find '/fsx-storygen/beidic/yang/c4_parts/downloads/c4_file15.json'Unable to find '/fsx-storygen/beidic/yang/c4_parts/downloads/c4_file15.json'FileNotFoundError

: Unable to find '/fsx-storygen/beidic/yang/c4_parts/downloads/c4_file15.json'
    train_dataset = CustomDataset(max_length = args.max_length, data_dir = dir_c4_parts, large_tokenizer = large_tokenizer, small_tokenizer = small_tokenizer, kernel_size = kernel_size, topk = args.topk, prompt_length = 64, use_c4 = args.use_c4, in_training = True) 
  File "/opt/hpcaas/.mounts/fs-03efe25c053395d1f/beidic/yang/transformersprofiling/largemodelfinetuning_mseplusceloss2.py", line 756, in __init__
    raise FileNotFoundError(error_msg)
FileNotFoundError: Unable to find '/fsx-storygen/beidic/yang/c4_parts/downloads/c4_file15.json'
    self.dataset = load_dataset('json', data_files = dfiles, split = "train") 
  File "/data/home/beidic/anaconda3/envs/yangllm2/lib/python3.9/site-packages/datasets/load.py", line 2548, in load_dataset
    builder_instance = load_dataset_builder(
  File "/data/home/beidic/anaconda3/envs/yangllm2/lib/python3.9/site-packages/datasets/load.py", line 2220, in load_dataset_builder
    dataset_module = dataset_module_factory(
  File "/data/home/beidic/anaconda3/envs/yangllm2/lib/python3.9/site-packages/datasets/load.py", line 1755, in dataset_module_factory
    return PackagedDatasetModuleFactory(
  File "/data/home/beidic/anaconda3/envs/yangllm2/lib/python3.9/site-packages/datasets/load.py", line 1129, in get_module
    data_files = DataFilesDict.from_patterns(
  File "/data/home/beidic/anaconda3/envs/yangllm2/lib/python3.9/site-packages/datasets/data_files.py", line 693, in from_patterns
    DataFilesList.from_patterns(
  File "/data/home/beidic/anaconda3/envs/yangllm2/lib/python3.9/site-packages/datasets/data_files.py", line 598, in from_patterns
    resolve_pattern(
  File "/data/home/beidic/anaconda3/envs/yangllm2/lib/python3.9/site-packages/datasets/data_files.py", line 386, in resolve_pattern
    raise FileNotFoundError(error_msg)
FileNotFoundError: Unable to find '/fsx-storygen/beidic/yang/c4_parts/downloads/c4_file15.json'
Traceback (most recent call last):
  File "/opt/hpcaas/.mounts/fs-03efe25c053395d1f/beidic/yang/transformersprofiling/largemodelfinetuning_mseplusceloss2.py", line 934, in <module>
    train_dataset = CustomDataset(max_length = args.max_length, data_dir = dir_c4_parts, large_tokenizer = large_tokenizer, small_tokenizer = small_tokenizer, kernel_size = kernel_size, topk = args.topk, prompt_length = 64, use_c4 = args.use_c4, in_training = True) 
  File "/opt/hpcaas/.mounts/fs-03efe25c053395d1f/beidic/yang/transformersprofiling/largemodelfinetuning_mseplusceloss2.py", line 756, in __init__
    self.dataset = load_dataset('json', data_files = dfiles, split = "train") 
  File "/data/home/beidic/anaconda3/envs/yangllm2/lib/python3.9/site-packages/datasets/load.py", line 2548, in load_dataset
    builder_instance = load_dataset_builder(
  File "/data/home/beidic/anaconda3/envs/yangllm2/lib/python3.9/site-packages/datasets/load.py", line 2220, in load_dataset_builder
    dataset_module = dataset_module_factory(
  File "/data/home/beidic/anaconda3/envs/yangllm2/lib/python3.9/site-packages/datasets/load.py", line 1755, in dataset_module_factory
    return PackagedDatasetModuleFactory(
  File "/data/home/beidic/anaconda3/envs/yangllm2/lib/python3.9/site-packages/datasets/load.py", line 1129, in get_module
    data_files = DataFilesDict.from_patterns(
  File "/data/home/beidic/anaconda3/envs/yangllm2/lib/python3.9/site-packages/datasets/data_files.py", line 693, in from_patterns
    DataFilesList.from_patterns(
  File "/data/home/beidic/anaconda3/envs/yangllm2/lib/python3.9/site-packages/datasets/data_files.py", line 598, in from_patterns
    resolve_pattern(
  File "/data/home/beidic/anaconda3/envs/yangllm2/lib/python3.9/site-packages/datasets/data_files.py", line 386, in resolve_pattern
    raise FileNotFoundError(error_msg)
FileNotFoundError: Unable to find '/fsx-storygen/beidic/yang/c4_parts/downloads/c4_file15.json'
Traceback (most recent call last):
  File "/opt/hpcaas/.mounts/fs-03efe25c053395d1f/beidic/yang/transformersprofiling/largemodelfinetuning_mseplusceloss2.py", line 934, in <module>
    train_dataset = CustomDataset(max_length = args.max_length, data_dir = dir_c4_parts, large_tokenizer = large_tokenizer, small_tokenizer = small_tokenizer, kernel_size = kernel_size, topk = args.topk, prompt_length = 64, use_c4 = args.use_c4, in_training = True) 
  File "/opt/hpcaas/.mounts/fs-03efe25c053395d1f/beidic/yang/transformersprofiling/largemodelfinetuning_mseplusceloss2.py", line 756, in __init__
    self.dataset = load_dataset('json', data_files = dfiles, split = "train") 
  File "/data/home/beidic/anaconda3/envs/yangllm2/lib/python3.9/site-packages/datasets/load.py", line 2548, in load_dataset
    builder_instance = load_dataset_builder(
  File "/data/home/beidic/anaconda3/envs/yangllm2/lib/python3.9/site-packages/datasets/load.py", line 2220, in load_dataset_builder
Traceback (most recent call last):
  File "/opt/hpcaas/.mounts/fs-03efe25c053395d1f/beidic/yang/transformersprofiling/largemodelfinetuning_mseplusceloss2.py", line 934, in <module>
    dataset_module = dataset_module_factory(
  File "/data/home/beidic/anaconda3/envs/yangllm2/lib/python3.9/site-packages/datasets/load.py", line 1755, in dataset_module_factory
    train_dataset = CustomDataset(max_length = args.max_length, data_dir = dir_c4_parts, large_tokenizer = large_tokenizer, small_tokenizer = small_tokenizer, kernel_size = kernel_size, topk = args.topk, prompt_length = 64, use_c4 = args.use_c4, in_training = True) 
  File "/opt/hpcaas/.mounts/fs-03efe25c053395d1f/beidic/yang/transformersprofiling/largemodelfinetuning_mseplusceloss2.py", line 756, in __init__
    return PackagedDatasetModuleFactory(
  File "/data/home/beidic/anaconda3/envs/yangllm2/lib/python3.9/site-packages/datasets/load.py", line 1129, in get_module
    self.dataset = load_dataset('json', data_files = dfiles, split = "train") 
  File "/data/home/beidic/anaconda3/envs/yangllm2/lib/python3.9/site-packages/datasets/load.py", line 2548, in load_dataset
    data_files = DataFilesDict.from_patterns(
  File "/data/home/beidic/anaconda3/envs/yangllm2/lib/python3.9/site-packages/datasets/data_files.py", line 693, in from_patterns
    builder_instance = load_dataset_builder(
  File "/data/home/beidic/anaconda3/envs/yangllm2/lib/python3.9/site-packages/datasets/load.py", line 2220, in load_dataset_builder
    DataFilesList.from_patterns(
  File "/data/home/beidic/anaconda3/envs/yangllm2/lib/python3.9/site-packages/datasets/data_files.py", line 598, in from_patterns
    resolve_pattern(
  File "/data/home/beidic/anaconda3/envs/yangllm2/lib/python3.9/site-packages/datasets/data_files.py", line 386, in resolve_pattern
    dataset_module = dataset_module_factory(
  File "/data/home/beidic/anaconda3/envs/yangllm2/lib/python3.9/site-packages/datasets/load.py", line 1755, in dataset_module_factory
    raise FileNotFoundError(error_msg)
FileNotFoundError: Unable to find '/fsx-storygen/beidic/yang/c4_parts/downloads/c4_file15.json'
    return PackagedDatasetModuleFactory(
  File "/data/home/beidic/anaconda3/envs/yangllm2/lib/python3.9/site-packages/datasets/load.py", line 1129, in get_module
    data_files = DataFilesDict.from_patterns(
  File "/data/home/beidic/anaconda3/envs/yangllm2/lib/python3.9/site-packages/datasets/data_files.py", line 693, in from_patterns
    DataFilesList.from_patterns(
  File "/data/home/beidic/anaconda3/envs/yangllm2/lib/python3.9/site-packages/datasets/data_files.py", line 598, in from_patterns
    resolve_pattern(
  File "/data/home/beidic/anaconda3/envs/yangllm2/lib/python3.9/site-packages/datasets/data_files.py", line 386, in resolve_pattern
    raise FileNotFoundError(error_msg)
FileNotFoundError: Unable to find '/fsx-storygen/beidic/yang/c4_parts/downloads/c4_file15.json'
[2024-03-11 07:22:41,162] torch.distributed.elastic.multiprocessing.api: [ERROR] failed (exitcode: 1) local_rank: 0 (pid: 2960263) of binary: /data/home/beidic/anaconda3/envs/yangllm2/bin/python3.9
Traceback (most recent call last):
  File "/data/home/beidic/anaconda3/envs/yangllm2/bin/accelerate", line 8, in <module>
    sys.exit(main())
  File "/data/home/beidic/anaconda3/envs/yangllm2/lib/python3.9/site-packages/accelerate/commands/accelerate_cli.py", line 47, in main
    args.func(args)
  File "/data/home/beidic/anaconda3/envs/yangllm2/lib/python3.9/site-packages/accelerate/commands/launch.py", line 1014, in launch_command
    multi_gpu_launcher(args)
  File "/data/home/beidic/anaconda3/envs/yangllm2/lib/python3.9/site-packages/accelerate/commands/launch.py", line 672, in multi_gpu_launcher
    distrib_run.run(args)
  File "/data/home/beidic/anaconda3/envs/yangllm2/lib/python3.9/site-packages/torch/distributed/run.py", line 797, in run
    elastic_launch(
  File "/data/home/beidic/anaconda3/envs/yangllm2/lib/python3.9/site-packages/torch/distributed/launcher/api.py", line 134, in __call__
    return launch_agent(self._config, self._entrypoint, list(args))
  File "/data/home/beidic/anaconda3/envs/yangllm2/lib/python3.9/site-packages/torch/distributed/launcher/api.py", line 264, in launch_agent
    raise ChildFailedError(
torch.distributed.elastic.multiprocessing.errors.ChildFailedError: 
============================================================
largemodelfinetuning_mseplusceloss2.py FAILED
------------------------------------------------------------
Failures:
[1]:
  time      : 2024-03-11_07:22:41
  host      : a100-st-p4de24xlarge-1061.fair-a100.hpcaas
  rank      : 1 (local_rank: 1)
  exitcode  : 1 (pid: 2960264)
  error_file: <N/A>
  traceback : To enable traceback see: https://pytorch.org/docs/stable/elastic/errors.html
[2]:
  time      : 2024-03-11_07:22:41
  host      : a100-st-p4de24xlarge-1061.fair-a100.hpcaas
  rank      : 2 (local_rank: 2)
  exitcode  : 1 (pid: 2960265)
  error_file: <N/A>
  traceback : To enable traceback see: https://pytorch.org/docs/stable/elastic/errors.html
[3]:
  time      : 2024-03-11_07:22:41
  host      : a100-st-p4de24xlarge-1061.fair-a100.hpcaas
  rank      : 3 (local_rank: 3)
  exitcode  : 1 (pid: 2960266)
  error_file: <N/A>
  traceback : To enable traceback see: https://pytorch.org/docs/stable/elastic/errors.html
[4]:
  time      : 2024-03-11_07:22:41
  host      : a100-st-p4de24xlarge-1061.fair-a100.hpcaas
  rank      : 4 (local_rank: 4)
  exitcode  : 1 (pid: 2960267)
  error_file: <N/A>
  traceback : To enable traceback see: https://pytorch.org/docs/stable/elastic/errors.html
[5]:
  time      : 2024-03-11_07:22:41
  host      : a100-st-p4de24xlarge-1061.fair-a100.hpcaas
  rank      : 5 (local_rank: 5)
  exitcode  : 1 (pid: 2960268)
  error_file: <N/A>
  traceback : To enable traceback see: https://pytorch.org/docs/stable/elastic/errors.html
[6]:
  time      : 2024-03-11_07:22:41
  host      : a100-st-p4de24xlarge-1061.fair-a100.hpcaas
  rank      : 6 (local_rank: 6)
  exitcode  : 1 (pid: 2960269)
  error_file: <N/A>
  traceback : To enable traceback see: https://pytorch.org/docs/stable/elastic/errors.html
[7]:
  time      : 2024-03-11_07:22:41
  host      : a100-st-p4de24xlarge-1061.fair-a100.hpcaas
  rank      : 7 (local_rank: 7)
  exitcode  : 1 (pid: 2960270)
  error_file: <N/A>
  traceback : To enable traceback see: https://pytorch.org/docs/stable/elastic/errors.html
------------------------------------------------------------
Root Cause (first observed failure):
[0]:
  time      : 2024-03-11_07:22:41
  host      : a100-st-p4de24xlarge-1061.fair-a100.hpcaas
  rank      : 0 (local_rank: 0)
  exitcode  : 1 (pid: 2960263)
  error_file: <N/A>
  traceback : To enable traceback see: https://pytorch.org/docs/stable/elastic/errors.html
============================================================
