Already on 'yangexp2'
WARNING: Ignoring invalid distribution ~rllib3 (/private/home/beidic/.conda/envs/griffin/lib/python3.12/site-packages)
WARNING: Skipping /private/home/beidic/.conda/envs/griffin/lib/python3.12/site-packages/~rllib3-2.2.1.dist-info due to invalid metadata entry 'name'
WARNING: Ignoring invalid distribution ~ackaging (/private/home/beidic/.conda/envs/griffin/lib/python3.12/site-packages)
WARNING: Skipping /private/home/beidic/.conda/envs/griffin/lib/python3.12/site-packages/~ackaging-24.0.dist-info due to invalid metadata entry 'name'
WARNING: Ignoring invalid distribution ~umpy (/private/home/beidic/.conda/envs/griffin/lib/python3.12/site-packages)
WARNING: Ignoring invalid distribution ~umpy (/private/home/beidic/.conda/envs/griffin/lib/python3.12/site-packages)
/var/spool/slurm//job28562610/slurm_script: line 55: 1621673 Segmentation fault      (core dumped) wandb login
/var/spool/slurm//job28562610/slurm_script: line 61: /private/home/beidic/.conda/envs/griffin/bin/huggingface-cli: No such file or directory
Traceback (most recent call last):
  File "/private/home/beidic/.conda/envs/griffin/lib/python3.12/site-packages/transformers/utils/import_utils.py", line 1390, in _get_module
    return importlib.import_module("." + module_name, self.__name__)
           ^^^^^^^^^^^^^^^^^^^^^^^^^^^^^^^^^^^^^^^^^^^^^^^^^^^^^^^^^
  File "/private/home/beidic/.conda/envs/griffin/lib/python3.12/importlib/__init__.py", line 90, in import_module
    return _bootstrap._gcd_import(name[level:], package, level)
           ^^^^^^^^^^^^^^^^^^^^^^^^^^^^^^^^^^^^^^^^^^^^^^^^^^^^
  File "<frozen importlib._bootstrap>", line 1387, in _gcd_import
  File "<frozen importlib._bootstrap>", line 1360, in _find_and_load
  File "<frozen importlib._bootstrap>", line 1310, in _find_and_load_unlocked
  File "<frozen importlib._bootstrap>", line 488, in _call_with_frames_removed
  File "<frozen importlib._bootstrap>", line 1387, in _gcd_import
  File "<frozen importlib._bootstrap>", line 1360, in _find_and_load
  File "<frozen importlib._bootstrap>", line 1331, in _find_and_load_unlocked
  File "<frozen importlib._bootstrap>", line 935, in _load_unlocked
  File "<frozen importlib._bootstrap_external>", line 994, in exec_module
  File "<frozen importlib._bootstrap>", line 488, in _call_with_frames_removed
  File "/private/home/beidic/.conda/envs/griffin/lib/python3.12/site-packages/transformers/models/__init__.py", line 15, in <module>
ImportError: cannot import name 'albert' from partially initialized module 'transformers.models' (most likely due to a circular import) (/private/home/beidic/.conda/envs/griffin/lib/python3.12/site-packages/transformers/models/__init__.py)

The above exception was the direct cause of the following exception:

Traceback (most recent call last):
  File "/private/home/beidic/.conda/envs/griffin/bin/accelerate", line 5, in <module>
    from accelerate.commands.accelerate_cli import main
  File "/private/home/beidic/.conda/envs/griffin/lib/python3.12/site-packages/accelerate/commands/accelerate_cli.py", line 21, in <module>
    from accelerate.commands.estimate import estimate_command_parser
  File "/private/home/beidic/.conda/envs/griffin/lib/python3.12/site-packages/accelerate/commands/estimate.py", line 32, in <module>
    from transformers import AutoConfig, AutoModel
  File "<frozen importlib._bootstrap>", line 1412, in _handle_fromlist
  File "/private/home/beidic/.conda/envs/griffin/lib/python3.12/site-packages/transformers/utils/import_utils.py", line 1380, in __getattr__
  File "/private/home/beidic/.conda/envs/griffin/lib/python3.12/site-packages/transformers/utils/import_utils.py", line 1392, in _get_module
RuntimeError: Failed to import transformers.models.auto because of the following error (look up to see its traceback):
cannot import name 'albert' from partially initialized module 'transformers.models' (most likely due to a circular import) (/private/home/beidic/.conda/envs/griffin/lib/python3.12/site-packages/transformers/models/__init__.py)
