ERROR: Could not install packages due to an OSError: [Errno 122] Disk quota exceeded: '/data/home/beidic/anaconda3/envs/yangllm2/lib/python3.9/site-packages/__editable__.transformers-4.36.0.dev0.pth'

wandb: Currently logged in as: stevenzhou0816100. Use `wandb login --relogin` to force relogin
/var/spool/slurmd/job1757868/slurm_script: line 52: transformers-cli: command not found
The following values were not passed to `accelerate launch` and had defaults used instead:
		More than one GPU was found, enabling multi-GPU training.
		If this was unintended please pass in `--num_processes=1`.
	`--mixed_precision` was set to a value of `'no'`
	`--dynamo_backend` was set to a value of `'no'`
To avoid this warning pass in values for each of the problematic parameters or run `accelerate config`.
Traceback (most recent call last):
  File "/opt/hpcaas/.mounts/fs-03efe25c053395d1f/beidic/yang/transformersprofiling/src/transformers/utils/import_utils.py", line 1353, in _get_module
    return importlib.import_module("." + module_name, self.__name__)
  File "/data/home/beidic/anaconda3/envs/yangllm2/lib/python3.9/importlib/__init__.py", line 127, in import_module
    return _bootstrap._gcd_import(name[level:], package, level)
  File "<frozen importlib._bootstrap>", line 1030, in _gcd_import
  File "<frozen importlib._bootstrap>", line 1007, in _find_and_load
  File "<frozen importlib._bootstrap>", line 986, in _find_and_load_unlocked
  File "<frozen importlib._bootstrap>", line 680, in _load_unlocked
  File "<frozen importlib._bootstrap_external>", line 850, in exec_module
  File "<frozen importlib._bootstrap>", line 228, in _call_with_frames_removed
  File "/opt/hpcaas/.mounts/fs-03efe25c053395d1f/beidic/yang/transformersprofiling/src/transformers/models/gpt_neox/modeling_gpt_neox.py", line 42, in <module>
    from transformers.generation_utils import GenerationMixin 
ModuleNotFoundError: No module named 'transformers'

The above exception was the direct cause of the following exception:

Traceback (most recent call last):
  File "/opt/hpcaas/.mounts/fs-03efe25c053395d1f/beidic/yang/transformersprofiling/weird_training_addinglarge.py", line 9, in <module>
    from src.transformers import GPTNeoXForCausalLM 
  File "<frozen importlib._bootstrap>", line 1055, in _handle_fromlist
  File "/opt/hpcaas/.mounts/fs-03efe25c053395d1f/beidic/yang/transformersprofiling/src/transformers/utils/import_utils.py", line 1344, in __getattr__
    value = getattr(module, name)
  File "/opt/hpcaas/.mounts/fs-03efe25c053395d1f/beidic/yang/transformersprofiling/src/transformers/utils/import_utils.py", line 1343, in __getattr__
    module = self._get_module(self._class_to_module[name])
  File "/opt/hpcaas/.mounts/fs-03efe25c053395d1f/beidic/yang/transformersprofiling/src/transformers/utils/import_utils.py", line 1355, in _get_module
    raise RuntimeError(
RuntimeError: Failed to import src.transformers.models.gpt_neox.modeling_gpt_neox because of the following error (look up to see its traceback):
No module named 'transformers'
Traceback (most recent call last):
  File "/opt/hpcaas/.mounts/fs-03efe25c053395d1f/beidic/yang/transformersprofiling/src/transformers/utils/import_utils.py", line 1353, in _get_module
Traceback (most recent call last):
  File "/opt/hpcaas/.mounts/fs-03efe25c053395d1f/beidic/yang/transformersprofiling/src/transformers/utils/import_utils.py", line 1353, in _get_module
    return importlib.import_module("." + module_name, self.__name__)
  File "/data/home/beidic/anaconda3/envs/yangllm2/lib/python3.9/importlib/__init__.py", line 127, in import_module
Traceback (most recent call last):
  File "/opt/hpcaas/.mounts/fs-03efe25c053395d1f/beidic/yang/transformersprofiling/src/transformers/utils/import_utils.py", line 1353, in _get_module
    return importlib.import_module("." + module_name, self.__name__)
  File "/data/home/beidic/anaconda3/envs/yangllm2/lib/python3.9/importlib/__init__.py", line 127, in import_module
    return _bootstrap._gcd_import(name[level:], package, level)
  File "<frozen importlib._bootstrap>", line 1030, in _gcd_import
  File "<frozen importlib._bootstrap>", line 1007, in _find_and_load
  File "<frozen importlib._bootstrap>", line 986, in _find_and_load_unlocked
  File "<frozen importlib._bootstrap>", line 680, in _load_unlocked
  File "<frozen importlib._bootstrap_external>", line 850, in exec_module
      File "<frozen importlib._bootstrap>", line 228, in _call_with_frames_removed
return importlib.import_module("." + module_name, self.__name__)
  File "/data/home/beidic/anaconda3/envs/yangllm2/lib/python3.9/importlib/__init__.py", line 127, in import_module
  File "/opt/hpcaas/.mounts/fs-03efe25c053395d1f/beidic/yang/transformersprofiling/src/transformers/models/gpt_neox/modeling_gpt_neox.py", line 42, in <module>
    return _bootstrap._gcd_import(name[level:], package, level)
  File "<frozen importlib._bootstrap>", line 1030, in _gcd_import
  File "<frozen importlib._bootstrap>", line 1007, in _find_and_load
  File "<frozen importlib._bootstrap>", line 986, in _find_and_load_unlocked
  File "<frozen importlib._bootstrap>", line 680, in _load_unlocked
    from transformers.generation_utils import GenerationMixin 
  File "<frozen importlib._bootstrap_external>", line 850, in exec_module
ModuleNotFoundError: No module named 'transformers'

The above exception was the direct cause of the following exception:

Traceback (most recent call last):
  File "/opt/hpcaas/.mounts/fs-03efe25c053395d1f/beidic/yang/transformersprofiling/weird_training_addinglarge.py", line 9, in <module>
  File "<frozen importlib._bootstrap>", line 228, in _call_with_frames_removed
  File "/opt/hpcaas/.mounts/fs-03efe25c053395d1f/beidic/yang/transformersprofiling/src/transformers/models/gpt_neox/modeling_gpt_neox.py", line 42, in <module>
    return _bootstrap._gcd_import(name[level:], package, level)
  File "<frozen importlib._bootstrap>", line 1030, in _gcd_import
  File "<frozen importlib._bootstrap>", line 1007, in _find_and_load
  File "<frozen importlib._bootstrap>", line 986, in _find_and_load_unlocked
  File "<frozen importlib._bootstrap>", line 680, in _load_unlocked
  File "<frozen importlib._bootstrap_external>", line 850, in exec_module
  File "<frozen importlib._bootstrap>", line 228, in _call_with_frames_removed
  File "/opt/hpcaas/.mounts/fs-03efe25c053395d1f/beidic/yang/transformersprofiling/src/transformers/models/gpt_neox/modeling_gpt_neox.py", line 42, in <module>
    from src.transformers import GPTNeoXForCausalLM 
  File "<frozen importlib._bootstrap>", line 1055, in _handle_fromlist
    from transformers.generation_utils import GenerationMixin 
ModuleNotFoundError: No module named 'transformers'  File "/opt/hpcaas/.mounts/fs-03efe25c053395d1f/beidic/yang/transformersprofiling/src/transformers/utils/import_utils.py", line 1344, in __getattr__


The above exception was the direct cause of the following exception:

Traceback (most recent call last):
  File "/opt/hpcaas/.mounts/fs-03efe25c053395d1f/beidic/yang/transformersprofiling/weird_training_addinglarge.py", line 9, in <module>
    from transformers.generation_utils import GenerationMixin 
ModuleNotFoundError: No module named 'transformers'

The above exception was the direct cause of the following exception:

Traceback (most recent call last):
  File "/opt/hpcaas/.mounts/fs-03efe25c053395d1f/beidic/yang/transformersprofiling/weird_training_addinglarge.py", line 9, in <module>
    from src.transformers import GPTNeoXForCausalLM 
  File "<frozen importlib._bootstrap>", line 1055, in _handle_fromlist
  File "/opt/hpcaas/.mounts/fs-03efe25c053395d1f/beidic/yang/transformersprofiling/src/transformers/utils/import_utils.py", line 1344, in __getattr__
    value = getattr(module, name)
  File "/opt/hpcaas/.mounts/fs-03efe25c053395d1f/beidic/yang/transformersprofiling/src/transformers/utils/import_utils.py", line 1343, in __getattr__
    from src.transformers import GPTNeoXForCausalLM 
  File "<frozen importlib._bootstrap>", line 1055, in _handle_fromlist
  File "/opt/hpcaas/.mounts/fs-03efe25c053395d1f/beidic/yang/transformersprofiling/src/transformers/utils/import_utils.py", line 1344, in __getattr__
    value = getattr(module, name)
  File "/opt/hpcaas/.mounts/fs-03efe25c053395d1f/beidic/yang/transformersprofiling/src/transformers/utils/import_utils.py", line 1343, in __getattr__
        module = self._get_module(self._class_to_module[name])value = getattr(module, name)

  File "/opt/hpcaas/.mounts/fs-03efe25c053395d1f/beidic/yang/transformersprofiling/src/transformers/utils/import_utils.py", line 1355, in _get_module
  File "/opt/hpcaas/.mounts/fs-03efe25c053395d1f/beidic/yang/transformersprofiling/src/transformers/utils/import_utils.py", line 1343, in __getattr__
    module = self._get_module(self._class_to_module[name])
  File "/opt/hpcaas/.mounts/fs-03efe25c053395d1f/beidic/yang/transformersprofiling/src/transformers/utils/import_utils.py", line 1355, in _get_module
    raise RuntimeError(
RuntimeError: Failed to import src.transformers.models.gpt_neox.modeling_gpt_neox because of the following error (look up to see its traceback):
No module named 'transformers'
    module = self._get_module(self._class_to_module[name])
  File "/opt/hpcaas/.mounts/fs-03efe25c053395d1f/beidic/yang/transformersprofiling/src/transformers/utils/import_utils.py", line 1355, in _get_module
    raise RuntimeError(
RuntimeError: Failed to import src.transformers.models.gpt_neox.modeling_gpt_neox because of the following error (look up to see its traceback):
No module named 'transformers'
    raise RuntimeError(
RuntimeError: Failed to import src.transformers.models.gpt_neox.modeling_gpt_neox because of the following error (look up to see its traceback):
No module named 'transformers'
Traceback (most recent call last):
  File "/opt/hpcaas/.mounts/fs-03efe25c053395d1f/beidic/yang/transformersprofiling/src/transformers/utils/import_utils.py", line 1353, in _get_module
    return importlib.import_module("." + module_name, self.__name__)
  File "/data/home/beidic/anaconda3/envs/yangllm2/lib/python3.9/importlib/__init__.py", line 127, in import_module
    return _bootstrap._gcd_import(name[level:], package, level)
  File "<frozen importlib._bootstrap>", line 1030, in _gcd_import
  File "<frozen importlib._bootstrap>", line 1007, in _find_and_load
  File "<frozen importlib._bootstrap>", line 986, in _find_and_load_unlocked
  File "<frozen importlib._bootstrap>", line 680, in _load_unlocked
  File "<frozen importlib._bootstrap_external>", line 850, in exec_module
  File "<frozen importlib._bootstrap>", line 228, in _call_with_frames_removed
  File "/opt/hpcaas/.mounts/fs-03efe25c053395d1f/beidic/yang/transformersprofiling/src/transformers/models/gpt_neox/modeling_gpt_neox.py", line 42, in <module>
    from transformers.generation_utils import GenerationMixin 
ModuleNotFoundError: No module named 'transformers'

The above exception was the direct cause of the following exception:

Traceback (most recent call last):
  File "/opt/hpcaas/.mounts/fs-03efe25c053395d1f/beidic/yang/transformersprofiling/weird_training_addinglarge.py", line 9, in <module>
    from src.transformers import GPTNeoXForCausalLM 
  File "<frozen importlib._bootstrap>", line 1055, in _handle_fromlist
  File "/opt/hpcaas/.mounts/fs-03efe25c053395d1f/beidic/yang/transformersprofiling/src/transformers/utils/import_utils.py", line 1344, in __getattr__
    value = getattr(module, name)
  File "/opt/hpcaas/.mounts/fs-03efe25c053395d1f/beidic/yang/transformersprofiling/src/transformers/utils/import_utils.py", line 1343, in __getattr__
    module = self._get_module(self._class_to_module[name])
  File "/opt/hpcaas/.mounts/fs-03efe25c053395d1f/beidic/yang/transformersprofiling/src/transformers/utils/import_utils.py", line 1355, in _get_module
    raise RuntimeError(
RuntimeError: Failed to import src.transformers.models.gpt_neox.modeling_gpt_neox because of the following error (look up to see its traceback):
No module named 'transformers'
Traceback (most recent call last):
  File "/opt/hpcaas/.mounts/fs-03efe25c053395d1f/beidic/yang/transformersprofiling/src/transformers/utils/import_utils.py", line 1353, in _get_module
    return importlib.import_module("." + module_name, self.__name__)
  File "/data/home/beidic/anaconda3/envs/yangllm2/lib/python3.9/importlib/__init__.py", line 127, in import_module
    return _bootstrap._gcd_import(name[level:], package, level)
  File "<frozen importlib._bootstrap>", line 1030, in _gcd_import
  File "<frozen importlib._bootstrap>", line 1007, in _find_and_load
  File "<frozen importlib._bootstrap>", line 986, in _find_and_load_unlocked
  File "<frozen importlib._bootstrap>", line 680, in _load_unlocked
  File "<frozen importlib._bootstrap_external>", line 850, in exec_module
  File "<frozen importlib._bootstrap>", line 228, in _call_with_frames_removed
  File "/opt/hpcaas/.mounts/fs-03efe25c053395d1f/beidic/yang/transformersprofiling/src/transformers/models/gpt_neox/modeling_gpt_neox.py", line 42, in <module>
    from transformers.generation_utils import GenerationMixin 
ModuleNotFoundError: No module named 'transformers'

The above exception was the direct cause of the following exception:

Traceback (most recent call last):
  File "/opt/hpcaas/.mounts/fs-03efe25c053395d1f/beidic/yang/transformersprofiling/weird_training_addinglarge.py", line 9, in <module>
    from src.transformers import GPTNeoXForCausalLM 
  File "<frozen importlib._bootstrap>", line 1055, in _handle_fromlist
  File "/opt/hpcaas/.mounts/fs-03efe25c053395d1f/beidic/yang/transformersprofiling/src/transformers/utils/import_utils.py", line 1344, in __getattr__
    value = getattr(module, name)
  File "/opt/hpcaas/.mounts/fs-03efe25c053395d1f/beidic/yang/transformersprofiling/src/transformers/utils/import_utils.py", line 1343, in __getattr__
    module = self._get_module(self._class_to_module[name])
  File "/opt/hpcaas/.mounts/fs-03efe25c053395d1f/beidic/yang/transformersprofiling/src/transformers/utils/import_utils.py", line 1355, in _get_module
    raise RuntimeError(
RuntimeError: Failed to import src.transformers.models.gpt_neox.modeling_gpt_neox because of the following error (look up to see its traceback):
No module named 'transformers'
Traceback (most recent call last):
  File "/opt/hpcaas/.mounts/fs-03efe25c053395d1f/beidic/yang/transformersprofiling/src/transformers/utils/import_utils.py", line 1353, in _get_module
    return importlib.import_module("." + module_name, self.__name__)
  File "/data/home/beidic/anaconda3/envs/yangllm2/lib/python3.9/importlib/__init__.py", line 127, in import_module
    return _bootstrap._gcd_import(name[level:], package, level)
  File "<frozen importlib._bootstrap>", line 1030, in _gcd_import
  File "<frozen importlib._bootstrap>", line 1007, in _find_and_load
  File "<frozen importlib._bootstrap>", line 986, in _find_and_load_unlocked
  File "<frozen importlib._bootstrap>", line 680, in _load_unlocked
  File "<frozen importlib._bootstrap_external>", line 850, in exec_module
  File "<frozen importlib._bootstrap>", line 228, in _call_with_frames_removed
  File "/opt/hpcaas/.mounts/fs-03efe25c053395d1f/beidic/yang/transformersprofiling/src/transformers/models/gpt_neox/modeling_gpt_neox.py", line 42, in <module>
    from transformers.generation_utils import GenerationMixin 
ModuleNotFoundError: No module named 'transformers'

The above exception was the direct cause of the following exception:

Traceback (most recent call last):
  File "/opt/hpcaas/.mounts/fs-03efe25c053395d1f/beidic/yang/transformersprofiling/weird_training_addinglarge.py", line 9, in <module>
    from src.transformers import GPTNeoXForCausalLM 
  File "<frozen importlib._bootstrap>", line 1055, in _handle_fromlist
  File "/opt/hpcaas/.mounts/fs-03efe25c053395d1f/beidic/yang/transformersprofiling/src/transformers/utils/import_utils.py", line 1344, in __getattr__
Traceback (most recent call last):
  File "/opt/hpcaas/.mounts/fs-03efe25c053395d1f/beidic/yang/transformersprofiling/src/transformers/utils/import_utils.py", line 1353, in _get_module
    value = getattr(module, name)
  File "/opt/hpcaas/.mounts/fs-03efe25c053395d1f/beidic/yang/transformersprofiling/src/transformers/utils/import_utils.py", line 1343, in __getattr__
    return importlib.import_module("." + module_name, self.__name__)
  File "/data/home/beidic/anaconda3/envs/yangllm2/lib/python3.9/importlib/__init__.py", line 127, in import_module
    module = self._get_module(self._class_to_module[name])
  File "/opt/hpcaas/.mounts/fs-03efe25c053395d1f/beidic/yang/transformersprofiling/src/transformers/utils/import_utils.py", line 1355, in _get_module
    return _bootstrap._gcd_import(name[level:], package, level)
  File "<frozen importlib._bootstrap>", line 1030, in _gcd_import
  File "<frozen importlib._bootstrap>", line 1007, in _find_and_load
  File "<frozen importlib._bootstrap>", line 986, in _find_and_load_unlocked
  File "<frozen importlib._bootstrap>", line 680, in _load_unlocked
  File "<frozen importlib._bootstrap_external>", line 850, in exec_module
    raise RuntimeError(  File "<frozen importlib._bootstrap>", line 228, in _call_with_frames_removed

RuntimeError: Failed to import src.transformers.models.gpt_neox.modeling_gpt_neox because of the following error (look up to see its traceback):
No module named 'transformers'
  File "/opt/hpcaas/.mounts/fs-03efe25c053395d1f/beidic/yang/transformersprofiling/src/transformers/models/gpt_neox/modeling_gpt_neox.py", line 42, in <module>
    from transformers.generation_utils import GenerationMixin 
ModuleNotFoundError: No module named 'transformers'

The above exception was the direct cause of the following exception:

Traceback (most recent call last):
  File "/opt/hpcaas/.mounts/fs-03efe25c053395d1f/beidic/yang/transformersprofiling/weird_training_addinglarge.py", line 9, in <module>
    from src.transformers import GPTNeoXForCausalLM 
  File "<frozen importlib._bootstrap>", line 1055, in _handle_fromlist
  File "/opt/hpcaas/.mounts/fs-03efe25c053395d1f/beidic/yang/transformersprofiling/src/transformers/utils/import_utils.py", line 1344, in __getattr__
    value = getattr(module, name)
  File "/opt/hpcaas/.mounts/fs-03efe25c053395d1f/beidic/yang/transformersprofiling/src/transformers/utils/import_utils.py", line 1343, in __getattr__
    module = self._get_module(self._class_to_module[name])
  File "/opt/hpcaas/.mounts/fs-03efe25c053395d1f/beidic/yang/transformersprofiling/src/transformers/utils/import_utils.py", line 1355, in _get_module
    raise RuntimeError(
RuntimeError: Failed to import src.transformers.models.gpt_neox.modeling_gpt_neox because of the following error (look up to see its traceback):
No module named 'transformers'
[2024-04-17 02:12:29,007] torch.distributed.elastic.multiprocessing.api: [ERROR] failed (exitcode: 1) local_rank: 0 (pid: 4107267) of binary: /data/home/beidic/anaconda3/envs/yangllm2/bin/python3.9
Traceback (most recent call last):
  File "/data/home/beidic/anaconda3/envs/yangllm2/bin/accelerate", line 8, in <module>
    sys.exit(main())
  File "/data/home/beidic/anaconda3/envs/yangllm2/lib/python3.9/site-packages/accelerate/commands/accelerate_cli.py", line 47, in main
    args.func(args)
  File "/data/home/beidic/anaconda3/envs/yangllm2/lib/python3.9/site-packages/accelerate/commands/launch.py", line 1014, in launch_command
    multi_gpu_launcher(args)
  File "/data/home/beidic/anaconda3/envs/yangllm2/lib/python3.9/site-packages/accelerate/commands/launch.py", line 672, in multi_gpu_launcher
    distrib_run.run(args)
  File "/data/home/beidic/anaconda3/envs/yangllm2/lib/python3.9/site-packages/torch/distributed/run.py", line 797, in run
    elastic_launch(
  File "/data/home/beidic/anaconda3/envs/yangllm2/lib/python3.9/site-packages/torch/distributed/launcher/api.py", line 134, in __call__
    return launch_agent(self._config, self._entrypoint, list(args))
  File "/data/home/beidic/anaconda3/envs/yangllm2/lib/python3.9/site-packages/torch/distributed/launcher/api.py", line 264, in launch_agent
    raise ChildFailedError(
torch.distributed.elastic.multiprocessing.errors.ChildFailedError: 
============================================================
weird_training_addinglarge.py FAILED
------------------------------------------------------------
Failures:
[1]:
  time      : 2024-04-17_02:12:29
  host      : a100-st-p4de24xlarge-1040.fair-a100.hpcaas
  rank      : 1 (local_rank: 1)
  exitcode  : 1 (pid: 4107268)
  error_file: <N/A>
  traceback : To enable traceback see: https://pytorch.org/docs/stable/elastic/errors.html
[2]:
  time      : 2024-04-17_02:12:29
  host      : a100-st-p4de24xlarge-1040.fair-a100.hpcaas
  rank      : 2 (local_rank: 2)
  exitcode  : 1 (pid: 4107269)
  error_file: <N/A>
  traceback : To enable traceback see: https://pytorch.org/docs/stable/elastic/errors.html
[3]:
  time      : 2024-04-17_02:12:29
  host      : a100-st-p4de24xlarge-1040.fair-a100.hpcaas
  rank      : 3 (local_rank: 3)
  exitcode  : 1 (pid: 4107270)
  error_file: <N/A>
  traceback : To enable traceback see: https://pytorch.org/docs/stable/elastic/errors.html
[4]:
  time      : 2024-04-17_02:12:29
  host      : a100-st-p4de24xlarge-1040.fair-a100.hpcaas
  rank      : 4 (local_rank: 4)
  exitcode  : 1 (pid: 4107271)
  error_file: <N/A>
  traceback : To enable traceback see: https://pytorch.org/docs/stable/elastic/errors.html
[5]:
  time      : 2024-04-17_02:12:29
  host      : a100-st-p4de24xlarge-1040.fair-a100.hpcaas
  rank      : 5 (local_rank: 5)
  exitcode  : 1 (pid: 4107272)
  error_file: <N/A>
  traceback : To enable traceback see: https://pytorch.org/docs/stable/elastic/errors.html
[6]:
  time      : 2024-04-17_02:12:29
  host      : a100-st-p4de24xlarge-1040.fair-a100.hpcaas
  rank      : 6 (local_rank: 6)
  exitcode  : 1 (pid: 4107273)
  error_file: <N/A>
  traceback : To enable traceback see: https://pytorch.org/docs/stable/elastic/errors.html
[7]:
  time      : 2024-04-17_02:12:29
  host      : a100-st-p4de24xlarge-1040.fair-a100.hpcaas
  rank      : 7 (local_rank: 7)
  exitcode  : 1 (pid: 4107274)
  error_file: <N/A>
  traceback : To enable traceback see: https://pytorch.org/docs/stable/elastic/errors.html
------------------------------------------------------------
Root Cause (first observed failure):
[0]:
  time      : 2024-04-17_02:12:29
  host      : a100-st-p4de24xlarge-1040.fair-a100.hpcaas
  rank      : 0 (local_rank: 0)
  exitcode  : 1 (pid: 4107267)
  error_file: <N/A>
  traceback : To enable traceback see: https://pytorch.org/docs/stable/elastic/errors.html
============================================================
