wandb: Currently logged in as: stevenzhou0816100. Use `wandb login --relogin` to force relogin
The following values were not passed to `accelerate launch` and had defaults used instead:
		More than one GPU was found, enabling multi-GPU training.
		If this was unintended please pass in `--num_processes=1`.
	`--mixed_precision` was set to a value of `'no'`
	`--dynamo_backend` was set to a value of `'no'`
To avoid this warning pass in values for each of the problematic parameters or run `accelerate config`.
Traceback (most recent call last):
  File "/opt/hpcaas/.mounts/fs-03efe25c053395d1f/beidic/yang/transformersprofiling/largemodelfinetuning_mseplusceloss2.py", line 935, in <module>
    test_dataset = CustomDataset(max_length = args.max_length, data_dir = dir_c4_parts, large_tokenizer = large_tokenizer, small_tokenizer = small_tokenizer, kernel_size = kernel_size, topk = args.topk, prompt_length = 64, use_c4 = args.use_c4, in_training = False) 
  File "/opt/hpcaas/.mounts/fs-03efe25c053395d1f/beidic/yang/transformersprofiling/largemodelfinetuning_mseplusceloss2.py", line 756, in __init__
    self.dataset = load_dataset('json', data_files = dfiles, split = "train") 
  File "/data/home/beidic/anaconda3/envs/yangllm2/lib/python3.9/site-packages/datasets/load.py", line 2548, in load_dataset
    builder_instance = load_dataset_builder(
  File "/data/home/beidic/anaconda3/envs/yangllm2/lib/python3.9/site-packages/datasets/load.py", line 2220, in load_dataset_builder
Traceback (most recent call last):
  File "/opt/hpcaas/.mounts/fs-03efe25c053395d1f/beidic/yang/transformersprofiling/largemodelfinetuning_mseplusceloss2.py", line 935, in <module>
    dataset_module = dataset_module_factory(
  File "/data/home/beidic/anaconda3/envs/yangllm2/lib/python3.9/site-packages/datasets/load.py", line 1755, in dataset_module_factory
    test_dataset = CustomDataset(max_length = args.max_length, data_dir = dir_c4_parts, large_tokenizer = large_tokenizer, small_tokenizer = small_tokenizer, kernel_size = kernel_size, topk = args.topk, prompt_length = 64, use_c4 = args.use_c4, in_training = False) 
  File "/opt/hpcaas/.mounts/fs-03efe25c053395d1f/beidic/yang/transformersprofiling/largemodelfinetuning_mseplusceloss2.py", line 756, in __init__
    self.dataset = load_dataset('json', data_files = dfiles, split = "train") 
  File "/data/home/beidic/anaconda3/envs/yangllm2/lib/python3.9/site-packages/datasets/load.py", line 2548, in load_dataset
    return PackagedDatasetModuleFactory(
  File "/data/home/beidic/anaconda3/envs/yangllm2/lib/python3.9/site-packages/datasets/load.py", line 1129, in get_module
    data_files = DataFilesDict.from_patterns(
  File "/data/home/beidic/anaconda3/envs/yangllm2/lib/python3.9/site-packages/datasets/data_files.py", line 693, in from_patterns
    builder_instance = load_dataset_builder(
  File "/data/home/beidic/anaconda3/envs/yangllm2/lib/python3.9/site-packages/datasets/load.py", line 2220, in load_dataset_builder
    DataFilesList.from_patterns(
  File "/data/home/beidic/anaconda3/envs/yangllm2/lib/python3.9/site-packages/datasets/data_files.py", line 598, in from_patterns
    dataset_module = dataset_module_factory(
  File "/data/home/beidic/anaconda3/envs/yangllm2/lib/python3.9/site-packages/datasets/load.py", line 1755, in dataset_module_factory
    resolve_pattern(
  File "/data/home/beidic/anaconda3/envs/yangllm2/lib/python3.9/site-packages/datasets/data_files.py", line 386, in resolve_pattern
    return PackagedDatasetModuleFactory(
  File "/data/home/beidic/anaconda3/envs/yangllm2/lib/python3.9/site-packages/datasets/load.py", line 1129, in get_module
    raise FileNotFoundError(error_msg)
FileNotFoundError: Unable to find '/fsx-storygen/beidic/yang/c4_parts/downloads/c4_file20.json'
    data_files = DataFilesDict.from_patterns(
  File "/data/home/beidic/anaconda3/envs/yangllm2/lib/python3.9/site-packages/datasets/data_files.py", line 693, in from_patterns
    DataFilesList.from_patterns(
  File "/data/home/beidic/anaconda3/envs/yangllm2/lib/python3.9/site-packages/datasets/data_files.py", line 598, in from_patterns
Traceback (most recent call last):
  File "/opt/hpcaas/.mounts/fs-03efe25c053395d1f/beidic/yang/transformersprofiling/largemodelfinetuning_mseplusceloss2.py", line 935, in <module>
    resolve_pattern(
  File "/data/home/beidic/anaconda3/envs/yangllm2/lib/python3.9/site-packages/datasets/data_files.py", line 386, in resolve_pattern
Traceback (most recent call last):
  File "/opt/hpcaas/.mounts/fs-03efe25c053395d1f/beidic/yang/transformersprofiling/largemodelfinetuning_mseplusceloss2.py", line 935, in <module>
    test_dataset = CustomDataset(max_length = args.max_length, data_dir = dir_c4_parts, large_tokenizer = large_tokenizer, small_tokenizer = small_tokenizer, kernel_size = kernel_size, topk = args.topk, prompt_length = 64, use_c4 = args.use_c4, in_training = False) 
  File "/opt/hpcaas/.mounts/fs-03efe25c053395d1f/beidic/yang/transformersprofiling/largemodelfinetuning_mseplusceloss2.py", line 756, in __init__
    test_dataset = CustomDataset(max_length = args.max_length, data_dir = dir_c4_parts, large_tokenizer = large_tokenizer, small_tokenizer = small_tokenizer, kernel_size = kernel_size, topk = args.topk, prompt_length = 64, use_c4 = args.use_c4, in_training = False) 
  File "/opt/hpcaas/.mounts/fs-03efe25c053395d1f/beidic/yang/transformersprofiling/largemodelfinetuning_mseplusceloss2.py", line 756, in __init__
    self.dataset = load_dataset('json', data_files = dfiles, split = "train") 
  File "/data/home/beidic/anaconda3/envs/yangllm2/lib/python3.9/site-packages/datasets/load.py", line 2548, in load_dataset
    self.dataset = load_dataset('json', data_files = dfiles, split = "train") 
  File "/data/home/beidic/anaconda3/envs/yangllm2/lib/python3.9/site-packages/datasets/load.py", line 2548, in load_dataset
    raise FileNotFoundError(error_msg)
FileNotFoundError: Unable to find '/fsx-storygen/beidic/yang/c4_parts/downloads/c4_file20.json'
    builder_instance = load_dataset_builder(
  File "/data/home/beidic/anaconda3/envs/yangllm2/lib/python3.9/site-packages/datasets/load.py", line 2220, in load_dataset_builder
    builder_instance = load_dataset_builder(
  File "/data/home/beidic/anaconda3/envs/yangllm2/lib/python3.9/site-packages/datasets/load.py", line 2220, in load_dataset_builder
    dataset_module = dataset_module_factory(
  File "/data/home/beidic/anaconda3/envs/yangllm2/lib/python3.9/site-packages/datasets/load.py", line 1755, in dataset_module_factory
    dataset_module = dataset_module_factory(
  File "/data/home/beidic/anaconda3/envs/yangllm2/lib/python3.9/site-packages/datasets/load.py", line 1755, in dataset_module_factory
Traceback (most recent call last):
      File "/opt/hpcaas/.mounts/fs-03efe25c053395d1f/beidic/yang/transformersprofiling/largemodelfinetuning_mseplusceloss2.py", line 935, in <module>
return PackagedDatasetModuleFactory(
  File "/data/home/beidic/anaconda3/envs/yangllm2/lib/python3.9/site-packages/datasets/load.py", line 1129, in get_module
    return PackagedDatasetModuleFactory(
  File "/data/home/beidic/anaconda3/envs/yangllm2/lib/python3.9/site-packages/datasets/load.py", line 1129, in get_module
    data_files = DataFilesDict.from_patterns(
  File "/data/home/beidic/anaconda3/envs/yangllm2/lib/python3.9/site-packages/datasets/data_files.py", line 693, in from_patterns
    data_files = DataFilesDict.from_patterns(
  File "/data/home/beidic/anaconda3/envs/yangllm2/lib/python3.9/site-packages/datasets/data_files.py", line 693, in from_patterns
    test_dataset = CustomDataset(max_length = args.max_length, data_dir = dir_c4_parts, large_tokenizer = large_tokenizer, small_tokenizer = small_tokenizer, kernel_size = kernel_size, topk = args.topk, prompt_length = 64, use_c4 = args.use_c4, in_training = False) 
  File "/opt/hpcaas/.mounts/fs-03efe25c053395d1f/beidic/yang/transformersprofiling/largemodelfinetuning_mseplusceloss2.py", line 756, in __init__
    DataFilesList.from_patterns(
  File "/data/home/beidic/anaconda3/envs/yangllm2/lib/python3.9/site-packages/datasets/data_files.py", line 598, in from_patterns
    DataFilesList.from_patterns(
  File "/data/home/beidic/anaconda3/envs/yangllm2/lib/python3.9/site-packages/datasets/data_files.py", line 598, in from_patterns
    resolve_pattern(
  File "/data/home/beidic/anaconda3/envs/yangllm2/lib/python3.9/site-packages/datasets/data_files.py", line 386, in resolve_pattern
    self.dataset = load_dataset('json', data_files = dfiles, split = "train") 
  File "/data/home/beidic/anaconda3/envs/yangllm2/lib/python3.9/site-packages/datasets/load.py", line 2548, in load_dataset
Traceback (most recent call last):
      File "/opt/hpcaas/.mounts/fs-03efe25c053395d1f/beidic/yang/transformersprofiling/largemodelfinetuning_mseplusceloss2.py", line 935, in <module>
raise FileNotFoundError(error_msg)
FileNotFoundError: Unable to find '/fsx-storygen/beidic/yang/c4_parts/downloads/c4_file20.json'
    resolve_pattern(
  File "/data/home/beidic/anaconda3/envs/yangllm2/lib/python3.9/site-packages/datasets/data_files.py", line 386, in resolve_pattern
    test_dataset = CustomDataset(max_length = args.max_length, data_dir = dir_c4_parts, large_tokenizer = large_tokenizer, small_tokenizer = small_tokenizer, kernel_size = kernel_size, topk = args.topk, prompt_length = 64, use_c4 = args.use_c4, in_training = False) 
  File "/opt/hpcaas/.mounts/fs-03efe25c053395d1f/beidic/yang/transformersprofiling/largemodelfinetuning_mseplusceloss2.py", line 756, in __init__
    builder_instance = load_dataset_builder(
  File "/data/home/beidic/anaconda3/envs/yangllm2/lib/python3.9/site-packages/datasets/load.py", line 2220, in load_dataset_builder
    raise FileNotFoundError(error_msg)
FileNotFoundError: Unable to find '/fsx-storygen/beidic/yang/c4_parts/downloads/c4_file20.json'
    self.dataset = load_dataset('json', data_files = dfiles, split = "train") 
  File "/data/home/beidic/anaconda3/envs/yangllm2/lib/python3.9/site-packages/datasets/load.py", line 2548, in load_dataset
    dataset_module = dataset_module_factory(
  File "/data/home/beidic/anaconda3/envs/yangllm2/lib/python3.9/site-packages/datasets/load.py", line 1755, in dataset_module_factory
    return PackagedDatasetModuleFactory(
  File "/data/home/beidic/anaconda3/envs/yangllm2/lib/python3.9/site-packages/datasets/load.py", line 1129, in get_module
    builder_instance = load_dataset_builder(
  File "/data/home/beidic/anaconda3/envs/yangllm2/lib/python3.9/site-packages/datasets/load.py", line 2220, in load_dataset_builder
    data_files = DataFilesDict.from_patterns(
  File "/data/home/beidic/anaconda3/envs/yangllm2/lib/python3.9/site-packages/datasets/data_files.py", line 693, in from_patterns
    dataset_module = dataset_module_factory(
  File "/data/home/beidic/anaconda3/envs/yangllm2/lib/python3.9/site-packages/datasets/load.py", line 1755, in dataset_module_factory
    DataFilesList.from_patterns(
  File "/data/home/beidic/anaconda3/envs/yangllm2/lib/python3.9/site-packages/datasets/data_files.py", line 598, in from_patterns
    return PackagedDatasetModuleFactory(
  File "/data/home/beidic/anaconda3/envs/yangllm2/lib/python3.9/site-packages/datasets/load.py", line 1129, in get_module
    resolve_pattern(
  File "/data/home/beidic/anaconda3/envs/yangllm2/lib/python3.9/site-packages/datasets/data_files.py", line 386, in resolve_pattern
    raise FileNotFoundError(error_msg)
FileNotFoundError: Unable to find '/fsx-storygen/beidic/yang/c4_parts/downloads/c4_file20.json'
    data_files = DataFilesDict.from_patterns(
  File "/data/home/beidic/anaconda3/envs/yangllm2/lib/python3.9/site-packages/datasets/data_files.py", line 693, in from_patterns
    DataFilesList.from_patterns(
  File "/data/home/beidic/anaconda3/envs/yangllm2/lib/python3.9/site-packages/datasets/data_files.py", line 598, in from_patterns
    resolve_pattern(
  File "/data/home/beidic/anaconda3/envs/yangllm2/lib/python3.9/site-packages/datasets/data_files.py", line 386, in resolve_pattern
    raise FileNotFoundError(error_msg)
FileNotFoundError: Unable to find '/fsx-storygen/beidic/yang/c4_parts/downloads/c4_file20.json'
Traceback (most recent call last):
  File "/opt/hpcaas/.mounts/fs-03efe25c053395d1f/beidic/yang/transformersprofiling/largemodelfinetuning_mseplusceloss2.py", line 935, in <module>
    test_dataset = CustomDataset(max_length = args.max_length, data_dir = dir_c4_parts, large_tokenizer = large_tokenizer, small_tokenizer = small_tokenizer, kernel_size = kernel_size, topk = args.topk, prompt_length = 64, use_c4 = args.use_c4, in_training = False) 
  File "/opt/hpcaas/.mounts/fs-03efe25c053395d1f/beidic/yang/transformersprofiling/largemodelfinetuning_mseplusceloss2.py", line 756, in __init__
    self.dataset = load_dataset('json', data_files = dfiles, split = "train") 
  File "/data/home/beidic/anaconda3/envs/yangllm2/lib/python3.9/site-packages/datasets/load.py", line 2548, in load_dataset
    builder_instance = load_dataset_builder(
  File "/data/home/beidic/anaconda3/envs/yangllm2/lib/python3.9/site-packages/datasets/load.py", line 2220, in load_dataset_builder
    dataset_module = dataset_module_factory(
  File "/data/home/beidic/anaconda3/envs/yangllm2/lib/python3.9/site-packages/datasets/load.py", line 1755, in dataset_module_factory
    return PackagedDatasetModuleFactory(
  File "/data/home/beidic/anaconda3/envs/yangllm2/lib/python3.9/site-packages/datasets/load.py", line 1129, in get_module
    data_files = DataFilesDict.from_patterns(
  File "/data/home/beidic/anaconda3/envs/yangllm2/lib/python3.9/site-packages/datasets/data_files.py", line 693, in from_patterns
    DataFilesList.from_patterns(
  File "/data/home/beidic/anaconda3/envs/yangllm2/lib/python3.9/site-packages/datasets/data_files.py", line 598, in from_patterns
    resolve_pattern(
  File "/data/home/beidic/anaconda3/envs/yangllm2/lib/python3.9/site-packages/datasets/data_files.py", line 386, in resolve_pattern
    raise FileNotFoundError(error_msg)
FileNotFoundError: Unable to find '/fsx-storygen/beidic/yang/c4_parts/downloads/c4_file20.json'
Traceback (most recent call last):
  File "/opt/hpcaas/.mounts/fs-03efe25c053395d1f/beidic/yang/transformersprofiling/largemodelfinetuning_mseplusceloss2.py", line 935, in <module>
    test_dataset = CustomDataset(max_length = args.max_length, data_dir = dir_c4_parts, large_tokenizer = large_tokenizer, small_tokenizer = small_tokenizer, kernel_size = kernel_size, topk = args.topk, prompt_length = 64, use_c4 = args.use_c4, in_training = False) 
  File "/opt/hpcaas/.mounts/fs-03efe25c053395d1f/beidic/yang/transformersprofiling/largemodelfinetuning_mseplusceloss2.py", line 756, in __init__
    self.dataset = load_dataset('json', data_files = dfiles, split = "train") 
  File "/data/home/beidic/anaconda3/envs/yangllm2/lib/python3.9/site-packages/datasets/load.py", line 2548, in load_dataset
    builder_instance = load_dataset_builder(
  File "/data/home/beidic/anaconda3/envs/yangllm2/lib/python3.9/site-packages/datasets/load.py", line 2220, in load_dataset_builder
    dataset_module = dataset_module_factory(
  File "/data/home/beidic/anaconda3/envs/yangllm2/lib/python3.9/site-packages/datasets/load.py", line 1755, in dataset_module_factory
    return PackagedDatasetModuleFactory(
  File "/data/home/beidic/anaconda3/envs/yangllm2/lib/python3.9/site-packages/datasets/load.py", line 1129, in get_module
    data_files = DataFilesDict.from_patterns(
  File "/data/home/beidic/anaconda3/envs/yangllm2/lib/python3.9/site-packages/datasets/data_files.py", line 693, in from_patterns
    DataFilesList.from_patterns(
  File "/data/home/beidic/anaconda3/envs/yangllm2/lib/python3.9/site-packages/datasets/data_files.py", line 598, in from_patterns
    resolve_pattern(
  File "/data/home/beidic/anaconda3/envs/yangllm2/lib/python3.9/site-packages/datasets/data_files.py", line 386, in resolve_pattern
    raise FileNotFoundError(error_msg)
FileNotFoundError: Unable to find '/fsx-storygen/beidic/yang/c4_parts/downloads/c4_file20.json'
[2024-03-12 01:43:17,460] torch.distributed.elastic.multiprocessing.api: [ERROR] failed (exitcode: 1) local_rank: 0 (pid: 752098) of binary: /data/home/beidic/anaconda3/envs/yangllm2/bin/python3.9
Traceback (most recent call last):
  File "/data/home/beidic/anaconda3/envs/yangllm2/bin/accelerate", line 8, in <module>
    sys.exit(main())
  File "/data/home/beidic/anaconda3/envs/yangllm2/lib/python3.9/site-packages/accelerate/commands/accelerate_cli.py", line 47, in main
    args.func(args)
  File "/data/home/beidic/anaconda3/envs/yangllm2/lib/python3.9/site-packages/accelerate/commands/launch.py", line 1014, in launch_command
    multi_gpu_launcher(args)
  File "/data/home/beidic/anaconda3/envs/yangllm2/lib/python3.9/site-packages/accelerate/commands/launch.py", line 672, in multi_gpu_launcher
    distrib_run.run(args)
  File "/data/home/beidic/anaconda3/envs/yangllm2/lib/python3.9/site-packages/torch/distributed/run.py", line 797, in run
    elastic_launch(
  File "/data/home/beidic/anaconda3/envs/yangllm2/lib/python3.9/site-packages/torch/distributed/launcher/api.py", line 134, in __call__
    return launch_agent(self._config, self._entrypoint, list(args))
  File "/data/home/beidic/anaconda3/envs/yangllm2/lib/python3.9/site-packages/torch/distributed/launcher/api.py", line 264, in launch_agent
    raise ChildFailedError(
torch.distributed.elastic.multiprocessing.errors.ChildFailedError: 
============================================================
largemodelfinetuning_mseplusceloss2.py FAILED
------------------------------------------------------------
Failures:
[1]:
  time      : 2024-03-12_01:43:17
  host      : a100-st-p4de24xlarge-1070.fair-a100.hpcaas
  rank      : 1 (local_rank: 1)
  exitcode  : 1 (pid: 752099)
  error_file: <N/A>
  traceback : To enable traceback see: https://pytorch.org/docs/stable/elastic/errors.html
[2]:
  time      : 2024-03-12_01:43:17
  host      : a100-st-p4de24xlarge-1070.fair-a100.hpcaas
  rank      : 2 (local_rank: 2)
  exitcode  : 1 (pid: 752100)
  error_file: <N/A>
  traceback : To enable traceback see: https://pytorch.org/docs/stable/elastic/errors.html
[3]:
  time      : 2024-03-12_01:43:17
  host      : a100-st-p4de24xlarge-1070.fair-a100.hpcaas
  rank      : 3 (local_rank: 3)
  exitcode  : 1 (pid: 752101)
  error_file: <N/A>
  traceback : To enable traceback see: https://pytorch.org/docs/stable/elastic/errors.html
[4]:
  time      : 2024-03-12_01:43:17
  host      : a100-st-p4de24xlarge-1070.fair-a100.hpcaas
  rank      : 4 (local_rank: 4)
  exitcode  : 1 (pid: 752102)
  error_file: <N/A>
  traceback : To enable traceback see: https://pytorch.org/docs/stable/elastic/errors.html
[5]:
  time      : 2024-03-12_01:43:17
  host      : a100-st-p4de24xlarge-1070.fair-a100.hpcaas
  rank      : 5 (local_rank: 5)
  exitcode  : 1 (pid: 752103)
  error_file: <N/A>
  traceback : To enable traceback see: https://pytorch.org/docs/stable/elastic/errors.html
[6]:
  time      : 2024-03-12_01:43:17
  host      : a100-st-p4de24xlarge-1070.fair-a100.hpcaas
  rank      : 6 (local_rank: 6)
  exitcode  : 1 (pid: 752104)
  error_file: <N/A>
  traceback : To enable traceback see: https://pytorch.org/docs/stable/elastic/errors.html
[7]:
  time      : 2024-03-12_01:43:17
  host      : a100-st-p4de24xlarge-1070.fair-a100.hpcaas
  rank      : 7 (local_rank: 7)
  exitcode  : 1 (pid: 752105)
  error_file: <N/A>
  traceback : To enable traceback see: https://pytorch.org/docs/stable/elastic/errors.html
------------------------------------------------------------
Root Cause (first observed failure):
[0]:
  time      : 2024-03-12_01:43:17
  host      : a100-st-p4de24xlarge-1070.fair-a100.hpcaas
  rank      : 0 (local_rank: 0)
  exitcode  : 1 (pid: 752098)
  error_file: <N/A>
  traceback : To enable traceback see: https://pytorch.org/docs/stable/elastic/errors.html
============================================================
